# Error handling with Promises

- When a promise is rejected, it `throws` an exception (Error instance).
- Or within the then block, if an error is encountered, execution will stop and program terminates.
- We can use the `catch` block to handle this error.
- In a promise chain, `catch` block handles errors for all the promises written above it.
- `catch` block does not stop the promise chain. It returns a new promise with value `undefined` by default which will be caught by the next then block.
- To really stop the chain, we have to rethrow the error, which return a rejected promise which will be caught by next catch block.

``` javascript
function asyncTask1() {
  return new Promise((resolve, reject) => {
    setTimeout(() => {
      reject("TASK 1 FAILED::");
    }, 1000);
  });
}

function asyncTask2() {
  return new Promise((resolve, reject) => {
    setTimeout(() => {
      resolve("Task 2 completed");
    }, 2000);
  });
}

asyncTask1()
  .then((data) => {
    console.log("BLOCK 1::");
    return asyncTask2();
  })
  .catch((err) => {
    console.log("CATCH 1::", err); // TASK 1 FAILED::
  })
  .then((data) => {
    console.log("BLOCK 2::", data); // undefined
  });

```

If we write catch at the bottom. Then if an error is raised, execution stops and it looks for the catch block. Hence, no intermediate chai will run.

``` javascript
asyncTask1()
  .then((data) => {
    console.log("BLOCK 1::");
    return asyncTask2();
  })
  .then((data) => {
    console.log("BLOCK 2::", data);
  })
  .catch((err) => {
    console.log("CATCH 1::", err); // TASK 1 FAILED::
  });
```
