# Async await

- We can use the `try`, `catch`, `finally` inside a async function to catch errors.


``` javascript
(async () => {
  try {
    const res1 = await asyncTask1();
    const res2 = await asyncTask2();
  } catch (error) {
    console.log(error);
  }
})();
```
