# Async await

## Why

## Readability and maintainability

- With callbacks and promises, we could end up with deeply nested code which can lead to callback hell or multi level method chains.
- This can make our code hard to read and debug.
- Moreover, JS is synchronous in nature.
- So, async/await allows you to write asynchronous code that looks synchronous, making it more readable and easier to maintain.
- Instead of chaining, we write code that looks synchronous.

``` javascript
// Callback Hell Example
fetch('url', (response) => {
  parseData(response, (parsedData) => {
    processData(parsedData, (result) => {
      console.log(result);
    });
  });
});

// Promise Chaining
fetch('url')
  .then(response => parseData(response))
  .then(parsedData => processData(parsedData))
  .then(result => console.log(result))
  .catch(error => console.error(error));
```

``` javascript
// Async/Await
async function handleData() {
  try {
    const response = await fetch('url');
    const parsedData = await parseData(response);
    const result = await processData(parsedData);
    console.log(result);
  } catch (error) {
    console.error(error);
  }
}
```

## Async function

- It is a function that always returns a promise.
- If we return a value from async function, promise gets fulfiled with that return value.
- If we do not explicitly return anything, it gets fulfiled with undefined.
- If an error is thrown the returned promise is rejected.

``` javascript
async function asyncTask() {}

console.log(asyncTask()); // Promise {<fulfilled>: undefined}
```

``` javascript
async function asyncTask() {
return 2;
}

console.log(asyncTask()); // Promise {<fulfilled>: 2}
```

``` javascript
async function asyncTask() {
  throw new Error("Task failed");
}

console.log(asyncTask()); // Promise {<rejected>: 'Task failed'}
```

## Await keyword

- Inside an async function, you can use await to pause execution until a Promise is resolved or rejected.
- With every promise we can use await keyword to pause execution untill that promise completes.


## Error handling

- We use try catch to handle errors.
- Whenever a promise rejects, it is treated as an error and will go to the catch block.

``` javascript
async function fetchData() {
  try {
    const userResponse = await fetch('https://api.example.com/user');
    const user = await userResponse.json();
    console.log('User:', user);
  } catch (error) {
    console.error('Failed to fetch user:', error.message);
  }

  try {
    const postsResponse = await fetch('https://api.example.com/posts');
    const posts = await postsResponse.json();
    console.log('Posts:', posts);
  } catch (error) {
    console.error('Failed to fetch posts:', error.message);
  }
}
```

``` javascript
async function fetchData() {
  try {
    const userResponse = await fetch('https://api.example.com/user');
    const user = await userResponse.json();

    const postsResponse = await fetch(`https://api.example.com/posts?userId=${user.id}`);
    const posts = await postsResponse.json();

    console.log('User:', user);
    console.log('Posts:', posts);
  } catch (error) {
    console.error('An error occurred:', error.message);
  }
}
```
